<?xml version="1.0"?>


<robot name="my_robot">

    <material name="grey">
        <color rgba="0.7 0.7 0.7 1.0"/>
    </material>
    
    <material name="green">
        <color rgba="0.0 0.6 0.0 1.0"/>
    </material>

    <material name="white">
        <color rgba="1.0 1.0 1.0 1.0"/>
    </material>   
    
    
<link name="base_footprint">
    
</link>


<joint name="base_joint" type="fixed">

    <parent link="base_footprint"/>
    <child link="base_link"/>
    <origin xyz="0.0 0.0 0.06" rpy="0.0 0.0 0.0"/>

</joint>


    <link name="base_link">
        <visual>
             
            <geometry>
                <box size="0.36 0.33 0.25"/>  <!--  model dimension in meter -->
            </geometry>
            
            <origin xyz="0.0 0.0 0.125" rpy="0.0 0.0 0.0"/>  <!-- position of the box -->
        
            <material name="green" />   
        </visual>


        <collision>
             <geometry>
                <box size="0.36 0.33 0.25"/>  <!--  model dimension in meter -->
            </geometry>
            
            <origin xyz="0.0 0.0 0.125" rpy="0.0 0.0 0.0"/>
        </collision>
        <inertial>
            <mass value="5"/>
        <inertia 
            ixx="0.0344" ixy="0.0" ixz="0.0"
            iyy="0.0452" iyz="0.0"
            izz="0.0346"/>
                </inertial>
    </link>


<link name="lidar_box_link">
    <visual>
        <geometry>
            <box size="0.039 0.039 0.021"/>
        </geometry>
        <origin xyz="0.0 0.0 0.0" rpy="0.0 0.0 0.0"/>
        <material name="white"/>
    </visual>

<collision>
        <geometry>
            <box size="0.035 0.035 0.02"/> <!-- Slightly smaller for safety margin -->
        </geometry>
        <origin xyz="0.0 0.0 0.0" rpy="0.0 0.0 0.0"/>
    </collision>


</link>

<joint name="lidar_box_joint" type="fixed">
    <parent link="base_link"/>
    <child link="lidar_box_link"/>
    <origin xyz="0.145 0.0 0.2605" rpy="0.0 0.0 0.0"/>
    
</joint>

    <link name="lidar_link">
        <visual>
            <geometry>
                <cylinder radius="0.0175" length="0.012"/>
            </geometry>

            <origin xyz="0.0 0.0 0.0" rpy="0.0 0.0 0.0"/>
            <material name="white"/>
        </visual>
    <collision>
      <geometry>
        <cylinder radius="0.04" length="0.05"/>
      </geometry>
    </collision>
    <inertial>
      <mass value="0.1"/>
      <origin xyz="0 0 0" rpy="0 0 0"/>
      <inertia 
        ixx="0.0001" ixy="0.0" ixz="0.0"
        iyy="0.0001" iyz="0.0"
        izz="0.00008"/>
    </inertial>
    </link>

    <joint name="base_lider_joint" type="fixed">
        <parent link="base_link"/>
        <child link="lidar_link"/>
        <origin xyz="0.145 0.0 0.276" rpy="0.0 0.0 0.0"/>  <!--change the -->
        
    </joint>

    <link name="front_left_wheel_link">
        <visual>
            <geometry>
                <cylinder radius="0.06" length="0.06"/>
            </geometry>
            <origin xyz="0.0 0.0 0.0" rpy="1.57 0.0 0.0"/>
            <material name="grey"/>
        </visual>
         <collision>
        <geometry><cylinder radius="0.06" length="0.05"/></geometry>
        <origin xyz="0 0 0" rpy="1.57 0 0"/>
    </collision>
    
    <inertial>
        <mass value="0.1"/>
        <inertia
            ixx="0.0003" ixy="0.0" ixz="0.0" iyy="0.0003" iyz="0.0" izz="0.0006"/>  <!-- (1/2)*mass*r² -->
    </inertial>
    </link>

    <joint name="base_front_left_joint" type="continuous">
        <parent link="base_link"/>
        <child link="front_left_wheel_link"/>
        <origin xyz="0.14 0.2 0.0" rpy="0.0 0.0 0.0"/>
        <axis xyz="0.0 1.0 0.0"/>
    </joint>


    <link name="back_left_wheel_link">
        <visual>
            <geometry>
                <cylinder radius="0.06" length="0.06"/>
            </geometry>
            <origin xyz="0.0 0.0 0.0" rpy="1.57 0.0 0.0"/>
            <material name="grey"/>
        </visual>
         <collision>
        <geometry><cylinder radius="0.06" length="0.05"/></geometry>
        <origin xyz="0 0 0" rpy="1.57 0 0"/>
    </collision>
    
    <inertial>
              <mass value="0.1"/>
        <inertia
            ixx="0.0003" ixy="0.0" ixz="0.0" iyy="0.0003" iyz="0.0" izz="0.0006"/>  <!-- (1/2)*mass*r² -->
    </inertial>
    </link>

    <joint name="base_back_left_joint" type="continuous">
        <parent link="base_link"/>
        <child link="back_left_wheel_link"/>
        <origin xyz="-0.14 0.2 0.0" rpy="0.0 0.0 0.0"/>
        <axis xyz="0.0 1.0 0.0"/>
    </joint>


    <link name="back_right_wheel_link">
        <visual>
            <geometry>
                <cylinder radius="0.06" length="0.06"/>
            </geometry>
            <origin xyz="0.0 0.0 0.0" rpy="1.57 0.0 0.0"/>
            <material name="grey"/>
        </visual>
         <collision>
        <geometry><cylinder radius="0.06" length="0.05"/></geometry>
        <origin xyz="0 0 0" rpy="1.57 0 0"/>
    </collision>
    
    <inertial>
              <mass value="0.1"/>
        <inertia
            ixx="0.0003" ixy="0.0" ixz="0.0" iyy="0.0003" iyz="0.0" izz="0.0006"/>  <!-- (1/2)*mass*r² -->
    </inertial>

    </link>

    <joint name="base_back_right_joint" type="continuous">
        <parent link="base_link"/>
        <child link="back_right_wheel_link"/>
        <origin xyz="-0.14 -0.2 0.0" rpy="0.0 0.0 0.0"/>
        <axis xyz="0.0 1.0 0.0"/>
    </joint>



    <link name="front_right_wheel_link">
        <visual>
            <geometry>
                <cylinder radius="0.06" length="0.06"/>
            </geometry>
            <origin xyz="0.0 0.0 0.0" rpy="1.57 0.0 0.0"/>
            <material name="grey"/>
        </visual>

         <collision>
        <geometry><cylinder radius="0.06" length="0.05"/></geometry>
        <origin xyz="0 0 0" rpy="1.57 0 0"/>
    </collision>
    
    <inertial>
              <mass value="0.1"/>
        <inertia
            ixx="0.0003" ixy="0.0" ixz="0.0" iyy="0.0003" iyz="0.0" izz="0.0006"/>  <!-- (1/2)*mass*r² -->
    </inertial>
        
    </link>

    <joint name="base_front_right_joint" type="continuous">
        <parent link="base_link"/>
        <child link="front_right_wheel_link"/>
        <origin xyz="0.14 -0.2 0.0" rpy="0.0 0.0 0.0"/>
        <axis xyz="0.0 1.0 0.0"/>
    </joint>

<link name="camera_link">
    <visual>
        <geometry>
            <box size="0.03 0.03 0.01"/>
        </geometry>
        <origin xyz="0.0 0.0 0.0" rpy="0.0 1.57 0.0"/>
        <material name="white"/>
    </visual>    

    <collision>
        <geometry>
            <box size="0.03 0.03 0.01"/>
        </geometry>
        <origin xyz="0.0 0.0 0.0" rpy="0.0 1.57 0.0"/>
    </collision>

</link>

<joint name="camera_base_joint" type="fixed">
    <parent link="base_link"/>
    <child link="camera_link"/>
    <origin xyz="0.18 0.0 0.15" rpy="0.0 0.0 0.0"/>
</joint>


 <!-- IMU Sensor Link -->
  <link name="imu_link">
    <visual>
      <geometry>
        <box size="0.03 0.03 0.01"/>
      </geometry>
      <origin xyz="0 0 0" rpy="0 0 0"/>
      <material name="blue">
        <color rgba="0.0 0.0 1.0 1.0"/>
      </material>
    </visual>
    <collision>
      <geometry>
        <box size="0.03 0.03 0.01"/>
      </geometry>
    </collision>
    <inertial>
      <mass value="0.05"/>
      <origin xyz="0 0 0" rpy="0 0 0"/>
      <inertia 
        ixx="0.000004" ixy="0.0" ixz="0.0"
        iyy="0.000004" iyz="0.0"
        izz="0.0000045"/>
    </inertial>
  </link>

  <joint name="imu_joint" type="fixed">
    <parent link="base_link"/>
    <child link="imu_link"/>
    <origin xyz="0.15 0 0.1" rpy="0 0 0"/>
  </joint>



<!--gazebo -->

<gazebo>
    <plugin name="gazebo_ros_control" filename="libgazebo_ros_control.so">
        <robotNamespace>/</robotNamespace>
        <robotSimType>gazebo_ros_control/DefaultRobotHWSim</robotSimType>
    </plugin>
</gazebo>


<gazebo reference="front_left_wheel_link">
    <mu1>0.01</mu1>
    <mu2>0.01</mu2>
    <kp>1000000.0</kp>
    <kd>100.0</kd>
     <maxVel>100.0</maxVel>  <!-- Velocity limiter -->
    <minDepth>0.0001</minDepth>  <!-- Surface penetration allowance -->
</gazebo>

<gazebo reference="front_right_wheel_link">
    <mu1>0.01</mu1>
    <mu2>0.01</mu2>
    <kp>1000000.0</kp>
    <kd>100.0</kd>
     <maxVel>100.0</maxVel>  <!-- Velocity limiter -->
    <minDepth>0.0001</minDepth>  <!-- Surface penetration allowance -->
</gazebo>

<gazebo reference="back_left_wheel_link">
    <mu1>0.01</mu1>
    <mu2>0.01</mu2>
    <kp>1000000.0</kp>
    <kd>100.0</kd>
     <maxVel>100.0</maxVel>  <!-- Velocity limiter -->
    <minDepth>0.0001</minDepth>  <!-- Surface penetration allowance -->
</gazebo>

<gazebo reference="back_right_wheel_link">
    <mu1>0.01</mu1>
    <mu2>0.01</mu2>
    <kp>1000000.0</kp>
    <kd>100.0</kd>
     <maxVel>100.0</maxVel>  <!-- Velocity limiter -->
    <minDepth>0.0001</minDepth>  <!-- Surface penetration allowance -->
</gazebo>


<gazebo>
    <plugin name="skid_steer_drive_controller" filename="libgazebo_ros_skid_steer_drive.so">
        <updateRate>100.0</updateRate>
        <robotNamespace>/</robotNamespace>
        <leftFrontJoint>base_front_left_joint</leftFrontJoint>
        <rightFrontJoint>base_front_right_joint</rightFrontJoint>
        <leftRearJoint>base_back_left_joint</leftRearJoint>
        <rightRearJoint>base_back_right_joint</rightRearJoint>
        <wheelSeparation>0.4</wheelSeparation> <!-- Distance between left/right wheels -->
        <wheelDiameter>0.12</wheelDiameter> <!-- 2*radius -->
        <torque>200.0</torque> <!-- Max motor torque -->
        <wheelTorque>50.0</wheelTorque> 
        <wheelAcceleration>10.0</wheelAcceleration>
        <commandTopic>cmd_vel</commandTopic> <!-- Subscribes to standard topic -->
        <odometryTopic>odom</odometryTopic>
        <odometryFrame>odom</odometryFrame>
        <robotBaseFrame>base_footprint</robotBaseFrame>
        <publishOdomTF>true</publishOdomTF>
    </plugin>
</gazebo>

<gazebo reference="lidar_link">
    <sensor type="ray" name="lidar_sensor">
        <pose>0 0 0 0 0 0</pose>
        <visualize>true</visualize>
        <update_rate>10</update_rate>
        <ray>
            <scan>
                <horizontal>
                    <samples>360</samples> <!-- 1 degree resolution -->
                    <resolution>1.0</resolution>
                    <min_angle>-3.14159</min_angle> <!-- -π -->
                    <max_angle>3.14159</max_angle> <!-- +π -->
                </horizontal>
                <vertical>
                    <samples>1</samples> <!-- 2D LiDAR -->
                </vertical>
            </scan>
            <range>
                <min>0.10</min> <!-- 10cm min range -->
                <max>10.0</max> <!-- 10m max range -->
                <resolution>0.01</resolution>
            </range>
            <noise>
                <type>gaussian</type>
                <mean>0.0</mean>
                <stddev>0.01</stddev>
            </noise>
        </ray>
        <plugin name="lidar_controller" filename="libgazebo_ros_laser.so">
            <topicName>scan</topicName>
            <frameName>lidar_link</frameName>
        </plugin>
    </sensor>
</gazebo>


<gazebo reference="camera_link">
    <sensor type="camera" name="camera_sensor">
        <update_rate>30</update_rate>
        <camera>
            <horizontal_fov>1.0472</horizontal_fov> <!-- 60 degrees -->
            <image>
                <width>640</width>
                <height>640</height>
                <format>R8G8B8</format>
            </image>
            <clip>
                <near>0.05</near>
                <far>30.0</far>
            </clip>
        </camera>
        <plugin name="camera_controller" filename="libgazebo_ros_camera.so">
            <alwaysOn>true</alwaysOn>
            <updateRate>0.0</updateRate>
            <cameraName>camera</cameraName>
            <imageTopicName>image_raw</imageTopicName>
            <cameraInfoTopicName>camera_info</cameraInfoTopicName>
            <frameName>camera_link</frameName>
            <hackBaseline>0.07</hackBaseline>
        </plugin>
    </sensor>
</gazebo>

<gazebo reference="base_link">
    <sensor type="imu" name="imu_sensor">
        <plugin name="imu_plugin" filename="libgazebo_ros_imu_sensor.so">
            <topicName>imu/data</topicName>
            <bodyName>base_link</bodyName>
            <updateRate>100.0</updateRate>
            <gaussianNoise>0.01</gaussianNoise>
        </plugin>
    </sensor>
</gazebo>

<gazebo>
    <plugin name="ground_truth_plugin" filename="libgazebo_ros_p3d.so">
        <frameName>base_footprint</frameName>
        <bodyName>base_link</bodyName>
        <topicName>ground_truth</topicName>
        <updateRate>50.0</updateRate>
    </plugin>
</gazebo>


<gazebo>
    <physics type="ode">
        <max_step_size>0.1</max_step_size>
        <real_time_update_rate>200</real_time_update_rate>
        <solver>
            <type>quick</type>
            <iters>50</iters>
            <sor>1.3</sor>
        </solver>
    </physics>
</gazebo>
</robot>